[14-May-24 11:43:00 - INFO] - root - Stop signal received (SIGINT). Exiting...
[14-May-24 11:43:00 - INFO] - bot - Bot stopped.
[14-May-24 11:43:09 - INFO] - bot - Bot Running..!

Created by 
https://t.me/stilloid
[14-May-24 11:43:09 - INFO] - bot - Lets roll
[14-May-24 11:45:13 - INFO] - root - Stop signal received (SIGINT). Exiting...
[14-May-24 11:45:13 - INFO] - bot - Bot stopped.
[14-May-24 11:45:21 - INFO] - bot - Bot Running..!

Created by 
https://t.me/stilloid
[14-May-24 11:45:21 - INFO] - bot - Lets roll
[14-May-24 11:48:43 - INFO] - root - Stop signal received (SIGINT). Exiting...
[14-May-24 11:48:43 - INFO] - bot - Bot stopped.
[14-May-24 11:48:52 - INFO] - bot - Bot Running..!

Created by 
https://t.me/stilloid
[14-May-24 11:48:52 - INFO] - bot - Lets roll
[14-May-24 11:49:10 - INFO] - root - Stop signal received (SIGINT). Exiting...
[14-May-24 11:49:10 - INFO] - bot - Bot stopped.
[14-May-24 11:49:19 - INFO] - bot - Bot Running..!

Created by 
https://t.me/stilloid
[14-May-24 11:49:19 - INFO] - bot - Lets roll
[14-May-24 11:51:29 - INFO] - root - Stop signal received (SIGINT). Exiting...
[14-May-24 11:51:29 - INFO] - bot - Bot stopped.
[14-May-24 11:51:38 - INFO] - bot - Bot Running..!

Created by 
https://t.me/stilloid
[14-May-24 11:51:38 - INFO] - bot - Lets roll
[15-May-24 16:07:58 - WARNING] - pyrogram.connection.connection - Unable to connect due to network issues: [WinError 1232] The network location cannot be reached. For information about network troubleshooting, see Windows Help
[15-May-24 16:07:59 - WARNING] - pyrogram.connection.connection - Unable to connect due to network issues: [WinError 1232] The network location cannot be reached. For information about network troubleshooting, see Windows Help
[15-May-24 16:08:00 - WARNING] - pyrogram.connection.connection - Unable to connect due to network issues: [WinError 1232] The network location cannot be reached. For information about network troubleshooting, see Windows Help
[15-May-24 16:08:01 - WARNING] - pyrogram.connection.connection - Connection failed! Trying again...
[15-May-24 16:08:01 - WARNING] - pyrogram.connection.connection - Unable to connect due to network issues: [WinError 1232] The network location cannot be reached. For information about network troubleshooting, see Windows Help
[15-May-24 16:08:02 - WARNING] - pyrogram.connection.connection - Unable to connect due to network issues: [WinError 1232] The network location cannot be reached. For information about network troubleshooting, see Windows Help
[15-May-24 17:44:25 - INFO] - root - Stop signal received (SIGINT). Exiting...
[15-May-24 17:44:25 - INFO] - bot - Bot stopped.
[15-May-24 17:50:10 - INFO] - bot - Bot Running..!

Created by 
https://t.me/stilloid
[15-May-24 17:50:10 - INFO] - bot - Lets roll
[15-May-24 18:17:20 - WARNING] - pyrogram.connection.connection - Unable to connect due to network issues: [WinError 1232] The network location cannot be reached. For information about network troubleshooting, see Windows Help
[15-May-24 18:17:21 - WARNING] - pyrogram.connection.connection - Unable to connect due to network issues: [WinError 1232] The network location cannot be reached. For information about network troubleshooting, see Windows Help
[15-May-24 18:17:22 - WARNING] - pyrogram.connection.connection - Unable to connect due to network issues: [WinError 1232] The network location cannot be reached. For information about network troubleshooting, see Windows Help
[15-May-24 18:17:23 - WARNING] - pyrogram.connection.connection - Connection failed! Trying again...
[15-May-24 18:17:23 - WARNING] - pyrogram.connection.connection - Unable to connect due to network issues: [WinError 1232] The network location cannot be reached. For information about network troubleshooting, see Windows Help
[15-May-24 18:17:24 - WARNING] - pyrogram.connection.connection - Unable to connect due to network issues: [WinError 1232] The network location cannot be reached. For information about network troubleshooting, see Windows Help
[15-May-24 18:17:25 - WARNING] - pyrogram.connection.connection - Unable to connect due to network issues: [WinError 1232] The network location cannot be reached. For information about network troubleshooting, see Windows Help
[15-May-24 18:17:26 - WARNING] - pyrogram.connection.connection - Connection failed! Trying again...
[15-May-24 18:17:26 - WARNING] - pyrogram.connection.connection - Unable to connect due to network issues: [WinError 1232] The network location cannot be reached. For information about network troubleshooting, see Windows Help
[15-May-24 18:17:27 - WARNING] - pyrogram.connection.connection - Unable to connect due to network issues: [WinError 1232] The network location cannot be reached. For information about network troubleshooting, see Windows Help
[15-May-24 20:47:42 - WARNING] - pyrogram.connection.connection - Unable to connect due to network issues: Connection timed out
[15-May-24 20:47:53 - WARNING] - pyrogram.connection.connection - Unable to connect due to network issues: Connection timed out
[15-May-24 20:48:04 - WARNING] - pyrogram.connection.connection - Unable to connect due to network issues: Connection timed out
[15-May-24 20:48:05 - WARNING] - pyrogram.connection.connection - Connection failed! Trying again...
[16-May-24 08:21:36 - WARNING] - pyrogram.connection.connection - Unable to connect due to network issues: [WinError 1231] The network location cannot be reached. For information about network troubleshooting, see Windows Help
[16-May-24 08:24:03 - ERROR] - pyrogram.dispatcher - 'NoneType' object has no attribute 'id'
Traceback (most recent call last):
  File "C:\Users\manfr\AppData\Roaming\Python\Python311\site-packages\pyrogram\dispatcher.py", line 240, in handler_worker
    await handler.callback(self.client, *args)
  File "C:\Users\manfr\AppData\Roaming\Python\Python311\site-packages\pyromod\listen\listen.py", line 93, in resolve_listener
    await self.user_callback(client, message, *args)
  File "C:\WorkSpace\Apps\Bots\File-Sharing-Bot\middlewares\__init__.py", line 9, in ensure_user_indb
    await check_and_add_user(msg.chat, msg.from_user)
  File "C:\WorkSpace\Apps\Bots\File-Sharing-Bot\helper_func.py", line 113, in check_and_add_user
    exists = await present_user(telegram_id=msg_from.id)
                                            ^^^^^^^^^^^
AttributeError: 'NoneType' object has no attribute 'id'
[16-May-24 08:24:43 - ERROR] - pyrogram.dispatcher - 'NoneType' object has no attribute 'id'
Traceback (most recent call last):
  File "C:\Users\manfr\AppData\Roaming\Python\Python311\site-packages\pyrogram\dispatcher.py", line 240, in handler_worker
    await handler.callback(self.client, *args)
  File "C:\Users\manfr\AppData\Roaming\Python\Python311\site-packages\pyromod\listen\listen.py", line 93, in resolve_listener
    await self.user_callback(client, message, *args)
  File "C:\WorkSpace\Apps\Bots\File-Sharing-Bot\middlewares\__init__.py", line 9, in ensure_user_indb
    await check_and_add_user(msg.chat, msg.from_user)
  File "C:\WorkSpace\Apps\Bots\File-Sharing-Bot\helper_func.py", line 113, in check_and_add_user
    exists = await present_user(telegram_id=msg_from.id)
                                            ^^^^^^^^^^^
AttributeError: 'NoneType' object has no attribute 'id'
[16-May-24 08:49:00 - WARNING] - pyrogram.connection.connection - Unable to connect due to network issues: [WinError 1236] The network connection was aborted by the local system
[16-May-24 10:01:15 - WARNING] - pyrogram.connection.connection - Unable to connect due to network issues: Connection timed out
[16-May-24 10:01:26 - WARNING] - pyrogram.connection.connection - Unable to connect due to network issues: Connection timed out
[16-May-24 13:32:40 - ERROR] - pyrogram.dispatcher - 'NoneType' object has no attribute 'id'
Traceback (most recent call last):
  File "C:\Users\manfr\AppData\Roaming\Python\Python311\site-packages\pyrogram\dispatcher.py", line 240, in handler_worker
    await handler.callback(self.client, *args)
  File "C:\Users\manfr\AppData\Roaming\Python\Python311\site-packages\pyromod\listen\listen.py", line 93, in resolve_listener
    await self.user_callback(client, message, *args)
  File "C:\WorkSpace\Apps\Bots\File-Sharing-Bot\middlewares\__init__.py", line 9, in ensure_user_indb
    await check_and_add_user(msg.chat, msg.from_user)
  File "C:\WorkSpace\Apps\Bots\File-Sharing-Bot\helper_func.py", line 113, in check_and_add_user
    exists = await present_user(telegram_id=msg_from.id)
                                            ^^^^^^^^^^^
AttributeError: 'NoneType' object has no attribute 'id'
[16-May-24 13:33:59 - WARNING] - pyrogram.connection.connection - Unable to connect due to network issues: Connection timed out
[16-May-24 14:15:33 - ERROR] - pyrogram.dispatcher - 'NoneType' object has no attribute 'id'
Traceback (most recent call last):
  File "C:\Users\manfr\AppData\Roaming\Python\Python311\site-packages\pyrogram\dispatcher.py", line 240, in handler_worker
    await handler.callback(self.client, *args)
  File "C:\Users\manfr\AppData\Roaming\Python\Python311\site-packages\pyromod\listen\listen.py", line 93, in resolve_listener
    await self.user_callback(client, message, *args)
  File "C:\WorkSpace\Apps\Bots\File-Sharing-Bot\middlewares\__init__.py", line 9, in ensure_user_indb
    await check_and_add_user(msg.chat, msg.from_user)
  File "C:\WorkSpace\Apps\Bots\File-Sharing-Bot\helper_func.py", line 113, in check_and_add_user
    exists = await present_user(telegram_id=msg_from.id)
                                            ^^^^^^^^^^^
AttributeError: 'NoneType' object has no attribute 'id'
[16-May-24 14:29:06 - ERROR] - pyrogram.dispatcher - 'NoneType' object has no attribute 'id'
Traceback (most recent call last):
  File "C:\Users\manfr\AppData\Roaming\Python\Python311\site-packages\pyrogram\dispatcher.py", line 240, in handler_worker
    await handler.callback(self.client, *args)
  File "C:\Users\manfr\AppData\Roaming\Python\Python311\site-packages\pyromod\listen\listen.py", line 93, in resolve_listener
    await self.user_callback(client, message, *args)
  File "C:\WorkSpace\Apps\Bots\File-Sharing-Bot\middlewares\__init__.py", line 9, in ensure_user_indb
    await check_and_add_user(msg.chat, msg.from_user)
  File "C:\WorkSpace\Apps\Bots\File-Sharing-Bot\helper_func.py", line 113, in check_and_add_user
    exists = await present_user(telegram_id=msg_from.id)
                                            ^^^^^^^^^^^
AttributeError: 'NoneType' object has no attribute 'id'
[16-May-24 14:32:20 - ERROR] - pyrogram.dispatcher - 'NoneType' object has no attribute 'id'
Traceback (most recent call last):
  File "C:\Users\manfr\AppData\Roaming\Python\Python311\site-packages\pyrogram\dispatcher.py", line 240, in handler_worker
    await handler.callback(self.client, *args)
  File "C:\Users\manfr\AppData\Roaming\Python\Python311\site-packages\pyromod\listen\listen.py", line 93, in resolve_listener
    await self.user_callback(client, message, *args)
  File "C:\WorkSpace\Apps\Bots\File-Sharing-Bot\middlewares\__init__.py", line 9, in ensure_user_indb
    await check_and_add_user(msg.chat, msg.from_user)
  File "C:\WorkSpace\Apps\Bots\File-Sharing-Bot\helper_func.py", line 113, in check_and_add_user
    exists = await present_user(telegram_id=msg_from.id)
                                            ^^^^^^^^^^^
AttributeError: 'NoneType' object has no attribute 'id'
[16-May-24 15:20:33 - ERROR] - pyrogram.dispatcher - 'NoneType' object has no attribute 'id'
Traceback (most recent call last):
  File "C:\Users\manfr\AppData\Roaming\Python\Python311\site-packages\pyrogram\dispatcher.py", line 240, in handler_worker
    await handler.callback(self.client, *args)
  File "C:\Users\manfr\AppData\Roaming\Python\Python311\site-packages\pyromod\listen\listen.py", line 93, in resolve_listener
    await self.user_callback(client, message, *args)
  File "C:\WorkSpace\Apps\Bots\File-Sharing-Bot\middlewares\__init__.py", line 9, in ensure_user_indb
    await check_and_add_user(msg.chat, msg.from_user)
  File "C:\WorkSpace\Apps\Bots\File-Sharing-Bot\helper_func.py", line 113, in check_and_add_user
    exists = await present_user(telegram_id=msg_from.id)
                                            ^^^^^^^^^^^
AttributeError: 'NoneType' object has no attribute 'id'
[16-May-24 15:43:50 - ERROR] - pyrogram.dispatcher - 'NoneType' object has no attribute 'id'
Traceback (most recent call last):
  File "C:\Users\manfr\AppData\Roaming\Python\Python311\site-packages\pyrogram\dispatcher.py", line 240, in handler_worker
    await handler.callback(self.client, *args)
  File "C:\Users\manfr\AppData\Roaming\Python\Python311\site-packages\pyromod\listen\listen.py", line 93, in resolve_listener
    await self.user_callback(client, message, *args)
  File "C:\WorkSpace\Apps\Bots\File-Sharing-Bot\middlewares\__init__.py", line 9, in ensure_user_indb
    await check_and_add_user(msg.chat, msg.from_user)
  File "C:\WorkSpace\Apps\Bots\File-Sharing-Bot\helper_func.py", line 113, in check_and_add_user
    exists = await present_user(telegram_id=msg_from.id)
                                            ^^^^^^^^^^^
AttributeError: 'NoneType' object has no attribute 'id'
[16-May-24 16:05:45 - ERROR] - pyrogram.dispatcher - 'NoneType' object has no attribute 'id'
Traceback (most recent call last):
  File "C:\Users\manfr\AppData\Roaming\Python\Python311\site-packages\pyrogram\dispatcher.py", line 240, in handler_worker
    await handler.callback(self.client, *args)
  File "C:\Users\manfr\AppData\Roaming\Python\Python311\site-packages\pyromod\listen\listen.py", line 93, in resolve_listener
    await self.user_callback(client, message, *args)
  File "C:\WorkSpace\Apps\Bots\File-Sharing-Bot\middlewares\__init__.py", line 9, in ensure_user_indb
    await check_and_add_user(msg.chat, msg.from_user)
  File "C:\WorkSpace\Apps\Bots\File-Sharing-Bot\helper_func.py", line 113, in check_and_add_user
    exists = await present_user(telegram_id=msg_from.id)
                                            ^^^^^^^^^^^
AttributeError: 'NoneType' object has no attribute 'id'
[16-May-24 17:01:59 - ERROR] - pyrogram.dispatcher - 'NoneType' object has no attribute 'id'
Traceback (most recent call last):
  File "C:\Users\manfr\AppData\Roaming\Python\Python311\site-packages\pyrogram\dispatcher.py", line 240, in handler_worker
    await handler.callback(self.client, *args)
  File "C:\Users\manfr\AppData\Roaming\Python\Python311\site-packages\pyromod\listen\listen.py", line 93, in resolve_listener
    await self.user_callback(client, message, *args)
  File "C:\WorkSpace\Apps\Bots\File-Sharing-Bot\middlewares\__init__.py", line 9, in ensure_user_indb
    await check_and_add_user(msg.chat, msg.from_user)
  File "C:\WorkSpace\Apps\Bots\File-Sharing-Bot\helper_func.py", line 113, in check_and_add_user
    exists = await present_user(telegram_id=msg_from.id)
                                            ^^^^^^^^^^^
AttributeError: 'NoneType' object has no attribute 'id'
[16-May-24 17:02:24 - ERROR] - pyrogram.dispatcher - 'NoneType' object has no attribute 'id'
Traceback (most recent call last):
  File "C:\Users\manfr\AppData\Roaming\Python\Python311\site-packages\pyrogram\dispatcher.py", line 240, in handler_worker
    await handler.callback(self.client, *args)
  File "C:\Users\manfr\AppData\Roaming\Python\Python311\site-packages\pyromod\listen\listen.py", line 93, in resolve_listener
    await self.user_callback(client, message, *args)
  File "C:\WorkSpace\Apps\Bots\File-Sharing-Bot\middlewares\__init__.py", line 9, in ensure_user_indb
    await check_and_add_user(msg.chat, msg.from_user)
  File "C:\WorkSpace\Apps\Bots\File-Sharing-Bot\helper_func.py", line 113, in check_and_add_user
    exists = await present_user(telegram_id=msg_from.id)
                                            ^^^^^^^^^^^
AttributeError: 'NoneType' object has no attribute 'id'
[16-May-24 17:02:39 - ERROR] - pyrogram.dispatcher - 'NoneType' object has no attribute 'id'
Traceback (most recent call last):
  File "C:\Users\manfr\AppData\Roaming\Python\Python311\site-packages\pyrogram\dispatcher.py", line 240, in handler_worker
    await handler.callback(self.client, *args)
  File "C:\Users\manfr\AppData\Roaming\Python\Python311\site-packages\pyromod\listen\listen.py", line 93, in resolve_listener
    await self.user_callback(client, message, *args)
  File "C:\WorkSpace\Apps\Bots\File-Sharing-Bot\middlewares\__init__.py", line 9, in ensure_user_indb
    await check_and_add_user(msg.chat, msg.from_user)
  File "C:\WorkSpace\Apps\Bots\File-Sharing-Bot\helper_func.py", line 113, in check_and_add_user
    exists = await present_user(telegram_id=msg_from.id)
                                            ^^^^^^^^^^^
AttributeError: 'NoneType' object has no attribute 'id'
[16-May-24 17:13:55 - ERROR] - pyrogram.dispatcher - 'NoneType' object has no attribute 'id'
Traceback (most recent call last):
  File "C:\Users\manfr\AppData\Roaming\Python\Python311\site-packages\pyrogram\dispatcher.py", line 240, in handler_worker
    await handler.callback(self.client, *args)
  File "C:\Users\manfr\AppData\Roaming\Python\Python311\site-packages\pyromod\listen\listen.py", line 93, in resolve_listener
    await self.user_callback(client, message, *args)
  File "C:\WorkSpace\Apps\Bots\File-Sharing-Bot\middlewares\__init__.py", line 9, in ensure_user_indb
    await check_and_add_user(msg.chat, msg.from_user)
  File "C:\WorkSpace\Apps\Bots\File-Sharing-Bot\helper_func.py", line 113, in check_and_add_user
    exists = await present_user(telegram_id=msg_from.id)
                                            ^^^^^^^^^^^
AttributeError: 'NoneType' object has no attribute 'id'
[16-May-24 17:16:01 - ERROR] - pyrogram.dispatcher - 'NoneType' object has no attribute 'id'
Traceback (most recent call last):
  File "C:\Users\manfr\AppData\Roaming\Python\Python311\site-packages\pyrogram\dispatcher.py", line 240, in handler_worker
    await handler.callback(self.client, *args)
  File "C:\Users\manfr\AppData\Roaming\Python\Python311\site-packages\pyromod\listen\listen.py", line 93, in resolve_listener
    await self.user_callback(client, message, *args)
  File "C:\WorkSpace\Apps\Bots\File-Sharing-Bot\middlewares\__init__.py", line 9, in ensure_user_indb
    await check_and_add_user(msg.chat, msg.from_user)
  File "C:\WorkSpace\Apps\Bots\File-Sharing-Bot\helper_func.py", line 113, in check_and_add_user
    exists = await present_user(telegram_id=msg_from.id)
                                            ^^^^^^^^^^^
AttributeError: 'NoneType' object has no attribute 'id'
[16-May-24 17:17:08 - ERROR] - pyrogram.dispatcher - 'NoneType' object has no attribute 'id'
Traceback (most recent call last):
  File "C:\Users\manfr\AppData\Roaming\Python\Python311\site-packages\pyrogram\dispatcher.py", line 240, in handler_worker
    await handler.callback(self.client, *args)
  File "C:\Users\manfr\AppData\Roaming\Python\Python311\site-packages\pyromod\listen\listen.py", line 93, in resolve_listener
    await self.user_callback(client, message, *args)
  File "C:\WorkSpace\Apps\Bots\File-Sharing-Bot\middlewares\__init__.py", line 9, in ensure_user_indb
    await check_and_add_user(msg.chat, msg.from_user)
  File "C:\WorkSpace\Apps\Bots\File-Sharing-Bot\helper_func.py", line 113, in check_and_add_user
    exists = await present_user(telegram_id=msg_from.id)
                                            ^^^^^^^^^^^
AttributeError: 'NoneType' object has no attribute 'id'
[16-May-24 17:22:27 - ERROR] - pyrogram.dispatcher - 'NoneType' object has no attribute 'id'
Traceback (most recent call last):
  File "C:\Users\manfr\AppData\Roaming\Python\Python311\site-packages\pyrogram\dispatcher.py", line 240, in handler_worker
    await handler.callback(self.client, *args)
  File "C:\Users\manfr\AppData\Roaming\Python\Python311\site-packages\pyromod\listen\listen.py", line 93, in resolve_listener
    await self.user_callback(client, message, *args)
  File "C:\WorkSpace\Apps\Bots\File-Sharing-Bot\middlewares\__init__.py", line 9, in ensure_user_indb
    await check_and_add_user(msg.chat, msg.from_user)
  File "C:\WorkSpace\Apps\Bots\File-Sharing-Bot\helper_func.py", line 113, in check_and_add_user
    exists = await present_user(telegram_id=msg_from.id)
                                            ^^^^^^^^^^^
AttributeError: 'NoneType' object has no attribute 'id'
[16-May-24 17:23:09 - ERROR] - pyrogram.dispatcher - 'NoneType' object has no attribute 'id'
Traceback (most recent call last):
  File "C:\Users\manfr\AppData\Roaming\Python\Python311\site-packages\pyrogram\dispatcher.py", line 240, in handler_worker
    await handler.callback(self.client, *args)
  File "C:\Users\manfr\AppData\Roaming\Python\Python311\site-packages\pyromod\listen\listen.py", line 93, in resolve_listener
    await self.user_callback(client, message, *args)
  File "C:\WorkSpace\Apps\Bots\File-Sharing-Bot\middlewares\__init__.py", line 9, in ensure_user_indb
    await check_and_add_user(msg.chat, msg.from_user)
  File "C:\WorkSpace\Apps\Bots\File-Sharing-Bot\helper_func.py", line 113, in check_and_add_user
    exists = await present_user(telegram_id=msg_from.id)
                                            ^^^^^^^^^^^
AttributeError: 'NoneType' object has no attribute 'id'
[16-May-24 17:40:46 - ERROR] - pyrogram.dispatcher - 'NoneType' object has no attribute 'id'
Traceback (most recent call last):
  File "C:\Users\manfr\AppData\Roaming\Python\Python311\site-packages\pyrogram\dispatcher.py", line 240, in handler_worker
    await handler.callback(self.client, *args)
  File "C:\Users\manfr\AppData\Roaming\Python\Python311\site-packages\pyromod\listen\listen.py", line 93, in resolve_listener
    await self.user_callback(client, message, *args)
  File "C:\WorkSpace\Apps\Bots\File-Sharing-Bot\middlewares\__init__.py", line 9, in ensure_user_indb
    await check_and_add_user(msg.chat, msg.from_user)
  File "C:\WorkSpace\Apps\Bots\File-Sharing-Bot\helper_func.py", line 113, in check_and_add_user
    exists = await present_user(telegram_id=msg_from.id)
                                            ^^^^^^^^^^^
AttributeError: 'NoneType' object has no attribute 'id'
[16-May-24 17:41:28 - ERROR] - pyrogram.dispatcher - 'NoneType' object has no attribute 'id'
Traceback (most recent call last):
  File "C:\Users\manfr\AppData\Roaming\Python\Python311\site-packages\pyrogram\dispatcher.py", line 240, in handler_worker
    await handler.callback(self.client, *args)
  File "C:\Users\manfr\AppData\Roaming\Python\Python311\site-packages\pyromod\listen\listen.py", line 93, in resolve_listener
    await self.user_callback(client, message, *args)
  File "C:\WorkSpace\Apps\Bots\File-Sharing-Bot\middlewares\__init__.py", line 9, in ensure_user_indb
    await check_and_add_user(msg.chat, msg.from_user)
  File "C:\WorkSpace\Apps\Bots\File-Sharing-Bot\helper_func.py", line 113, in check_and_add_user
    exists = await present_user(telegram_id=msg_from.id)
                                            ^^^^^^^^^^^
AttributeError: 'NoneType' object has no attribute 'id'
[16-May-24 18:20:42 - ERROR] - pyrogram.dispatcher - 'NoneType' object has no attribute 'id'
Traceback (most recent call last):
  File "C:\Users\manfr\AppData\Roaming\Python\Python311\site-packages\pyrogram\dispatcher.py", line 240, in handler_worker
    await handler.callback(self.client, *args)
  File "C:\Users\manfr\AppData\Roaming\Python\Python311\site-packages\pyromod\listen\listen.py", line 93, in resolve_listener
    await self.user_callback(client, message, *args)
  File "C:\WorkSpace\Apps\Bots\File-Sharing-Bot\middlewares\__init__.py", line 9, in ensure_user_indb
    await check_and_add_user(msg.chat, msg.from_user)
  File "C:\WorkSpace\Apps\Bots\File-Sharing-Bot\helper_func.py", line 113, in check_and_add_user
    exists = await present_user(telegram_id=msg_from.id)
                                            ^^^^^^^^^^^
AttributeError: 'NoneType' object has no attribute 'id'
[17-May-24 11:31:37 - ERROR] - pyrogram.dispatcher - 'NoneType' object has no attribute 'id'
Traceback (most recent call last):
  File "C:\Users\manfr\AppData\Roaming\Python\Python311\site-packages\pyrogram\dispatcher.py", line 240, in handler_worker
    await handler.callback(self.client, *args)
  File "C:\Users\manfr\AppData\Roaming\Python\Python311\site-packages\pyromod\listen\listen.py", line 93, in resolve_listener
    await self.user_callback(client, message, *args)
  File "C:\WorkSpace\Apps\Bots\File-Sharing-Bot\middlewares\__init__.py", line 9, in ensure_user_indb
    await check_and_add_user(msg.chat, msg.from_user)
  File "C:\WorkSpace\Apps\Bots\File-Sharing-Bot\helper_func.py", line 113, in check_and_add_user
    exists = await present_user(telegram_id=msg_from.id)
                                            ^^^^^^^^^^^
AttributeError: 'NoneType' object has no attribute 'id'
[17-May-24 13:29:27 - ERROR] - pyrogram.dispatcher - 'NoneType' object has no attribute 'id'
Traceback (most recent call last):
  File "C:\Users\manfr\AppData\Roaming\Python\Python311\site-packages\pyrogram\dispatcher.py", line 240, in handler_worker
    await handler.callback(self.client, *args)
  File "C:\Users\manfr\AppData\Roaming\Python\Python311\site-packages\pyromod\listen\listen.py", line 93, in resolve_listener
    await self.user_callback(client, message, *args)
  File "C:\WorkSpace\Apps\Bots\File-Sharing-Bot\middlewares\__init__.py", line 9, in ensure_user_indb
    await check_and_add_user(msg.chat, msg.from_user)
  File "C:\WorkSpace\Apps\Bots\File-Sharing-Bot\helper_func.py", line 113, in check_and_add_user
    exists = await present_user(telegram_id=msg_from.id)
                                            ^^^^^^^^^^^
AttributeError: 'NoneType' object has no attribute 'id'
[17-May-24 13:30:08 - ERROR] - pyrogram.dispatcher - 'NoneType' object has no attribute 'id'
Traceback (most recent call last):
  File "C:\Users\manfr\AppData\Roaming\Python\Python311\site-packages\pyrogram\dispatcher.py", line 240, in handler_worker
    await handler.callback(self.client, *args)
  File "C:\Users\manfr\AppData\Roaming\Python\Python311\site-packages\pyromod\listen\listen.py", line 93, in resolve_listener
    await self.user_callback(client, message, *args)
  File "C:\WorkSpace\Apps\Bots\File-Sharing-Bot\middlewares\__init__.py", line 9, in ensure_user_indb
    await check_and_add_user(msg.chat, msg.from_user)
  File "C:\WorkSpace\Apps\Bots\File-Sharing-Bot\helper_func.py", line 113, in check_and_add_user
    exists = await present_user(telegram_id=msg_from.id)
                                            ^^^^^^^^^^^
AttributeError: 'NoneType' object has no attribute 'id'
[17-May-24 13:37:28 - ERROR] - pyrogram.dispatcher - 'NoneType' object has no attribute 'id'
Traceback (most recent call last):
  File "C:\Users\manfr\AppData\Roaming\Python\Python311\site-packages\pyrogram\dispatcher.py", line 240, in handler_worker
    await handler.callback(self.client, *args)
  File "C:\Users\manfr\AppData\Roaming\Python\Python311\site-packages\pyromod\listen\listen.py", line 93, in resolve_listener
    await self.user_callback(client, message, *args)
  File "C:\WorkSpace\Apps\Bots\File-Sharing-Bot\middlewares\__init__.py", line 9, in ensure_user_indb
    await check_and_add_user(msg.chat, msg.from_user)
  File "C:\WorkSpace\Apps\Bots\File-Sharing-Bot\helper_func.py", line 113, in check_and_add_user
    exists = await present_user(telegram_id=msg_from.id)
                                            ^^^^^^^^^^^
AttributeError: 'NoneType' object has no attribute 'id'
[17-May-24 15:32:50 - WARNING] - pyrogram.connection.connection - Unable to connect due to network issues: Connection timed out
[17-May-24 15:33:01 - WARNING] - pyrogram.connection.connection - Unable to connect due to network issues: Connection timed out
[17-May-24 15:33:12 - WARNING] - pyrogram.connection.connection - Unable to connect due to network issues: Connection timed out
[17-May-24 15:33:13 - WARNING] - pyrogram.connection.connection - Connection failed! Trying again...
[17-May-24 15:47:08 - WARNING] - pyrogram.connection.connection - Unable to connect due to network issues: Connection timed out
[17-May-24 15:47:19 - WARNING] - pyrogram.connection.connection - Unable to connect due to network issues: Connection timed out
[17-May-24 15:47:59 - WARNING] - pyrogram.connection.connection - Unable to connect due to network issues: Connection timed out
[17-May-24 15:48:10 - WARNING] - pyrogram.connection.connection - Unable to connect due to network issues: Connection timed out
[17-May-24 15:51:27 - WARNING] - pyrogram.connection.connection - Unable to connect due to network issues: Connection timed out
[17-May-24 15:51:38 - WARNING] - pyrogram.connection.connection - Unable to connect due to network issues: Connection timed out
[17-May-24 15:55:24 - WARNING] - pyrogram.connection.connection - Unable to connect due to network issues: Connection timed out
[17-May-24 16:02:35 - WARNING] - pyrogram.connection.connection - Unable to connect due to network issues: Connection timed out
[17-May-24 16:02:46 - WARNING] - pyrogram.connection.connection - Unable to connect due to network issues: Connection timed out
[17-May-24 16:02:57 - WARNING] - pyrogram.connection.connection - Unable to connect due to network issues: Connection timed out
[17-May-24 16:02:58 - WARNING] - pyrogram.connection.connection - Connection failed! Trying again...
[17-May-24 16:03:08 - WARNING] - pyrogram.connection.connection - Unable to connect due to network issues: Connection timed out
[17-May-24 16:03:16 - WARNING] - pyrogram.connection.connection - Unable to connect due to network issues: [WinError 1231] The network location cannot be reached. For information about network troubleshooting, see Windows Help
[17-May-24 16:03:17 - WARNING] - pyrogram.connection.connection - Unable to connect due to network issues: [WinError 1231] The network location cannot be reached. For information about network troubleshooting, see Windows Help
[17-May-24 16:03:18 - WARNING] - pyrogram.connection.connection - Unable to connect due to network issues: [WinError 1231] The network location cannot be reached. For information about network troubleshooting, see Windows Help
[17-May-24 16:03:19 - WARNING] - pyrogram.connection.connection - Connection failed! Trying again...
[17-May-24 16:03:19 - WARNING] - pyrogram.connection.connection - Unable to connect due to network issues: [WinError 1231] The network location cannot be reached. For information about network troubleshooting, see Windows Help
[17-May-24 16:08:28 - WARNING] - pyrogram.connection.connection - Unable to connect due to network issues: Connection timed out
[17-May-24 16:08:39 - WARNING] - pyrogram.connection.connection - Unable to connect due to network issues: Connection timed out
[17-May-24 16:08:50 - WARNING] - pyrogram.connection.connection - Unable to connect due to network issues: Connection timed out
[17-May-24 16:08:51 - WARNING] - pyrogram.connection.connection - Connection failed! Trying again...
[17-May-24 16:09:01 - WARNING] - pyrogram.connection.connection - Unable to connect due to network issues: Connection timed out
[17-May-24 16:09:09 - WARNING] - pyrogram.connection.connection - Unable to connect due to network issues: [WinError 1236] The network connection was aborted by the local system
[17-May-24 16:09:10 - WARNING] - pyrogram.connection.connection - Unable to connect due to network issues: [WinError 1231] The network location cannot be reached. For information about network troubleshooting, see Windows Help
[17-May-24 16:09:11 - WARNING] - pyrogram.connection.connection - Connection failed! Trying again...
[17-May-24 16:09:11 - WARNING] - pyrogram.connection.connection - Unable to connect due to network issues: [WinError 1231] The network location cannot be reached. For information about network troubleshooting, see Windows Help
[17-May-24 16:09:12 - WARNING] - pyrogram.connection.connection - Unable to connect due to network issues: [WinError 1231] The network location cannot be reached. For information about network troubleshooting, see Windows Help
[17-May-24 16:25:27 - WARNING] - pyrogram.connection.connection - Unable to connect due to network issues: Connection timed out
[17-May-24 16:25:38 - WARNING] - pyrogram.connection.connection - Unable to connect due to network issues: Connection timed out
[17-May-24 16:25:50 - WARNING] - pyrogram.connection.connection - Unable to connect due to network issues: Connection timed out
[17-May-24 16:25:51 - WARNING] - pyrogram.connection.connection - Connection failed! Trying again...
[17-May-24 16:26:01 - WARNING] - pyrogram.connection.connection - Unable to connect due to network issues: Connection timed out
[17-May-24 16:26:09 - WARNING] - pyrogram.connection.connection - Unable to connect due to network issues: [WinError 1231] The network location cannot be reached. For information about network troubleshooting, see Windows Help
[17-May-24 16:26:10 - WARNING] - pyrogram.connection.connection - Unable to connect due to network issues: [WinError 1231] The network location cannot be reached. For information about network troubleshooting, see Windows Help
[17-May-24 16:26:11 - WARNING] - pyrogram.connection.connection - Unable to connect due to network issues: [WinError 1231] The network location cannot be reached. For information about network troubleshooting, see Windows Help
[17-May-24 16:26:12 - WARNING] - pyrogram.connection.connection - Connection failed! Trying again...
[17-May-24 16:26:12 - WARNING] - pyrogram.connection.connection - Unable to connect due to network issues: [WinError 1231] The network location cannot be reached. For information about network troubleshooting, see Windows Help
[17-May-24 18:41:37 - WARNING] - pyrogram.connection.connection - Unable to connect due to network issues: Connection timed out
[17-May-24 19:47:09 - ERROR] - pyrogram.dispatcher - 'NoneType' object has no attribute 'id'
Traceback (most recent call last):
  File "C:\Users\manfr\AppData\Roaming\Python\Python311\site-packages\pyrogram\dispatcher.py", line 240, in handler_worker
    await handler.callback(self.client, *args)
  File "C:\Users\manfr\AppData\Roaming\Python\Python311\site-packages\pyromod\listen\listen.py", line 93, in resolve_listener
    await self.user_callback(client, message, *args)
  File "C:\WorkSpace\Apps\Bots\File-Sharing-Bot\middlewares\__init__.py", line 9, in ensure_user_indb
    await check_and_add_user(msg.chat, msg.from_user)
  File "C:\WorkSpace\Apps\Bots\File-Sharing-Bot\helper_func.py", line 113, in check_and_add_user
    exists = await present_user(telegram_id=msg_from.id)
                                            ^^^^^^^^^^^
AttributeError: 'NoneType' object has no attribute 'id'
[17-May-24 19:47:55 - ERROR] - pyrogram.dispatcher - 'NoneType' object has no attribute 'id'
Traceback (most recent call last):
  File "C:\Users\manfr\AppData\Roaming\Python\Python311\site-packages\pyrogram\dispatcher.py", line 240, in handler_worker
    await handler.callback(self.client, *args)
  File "C:\Users\manfr\AppData\Roaming\Python\Python311\site-packages\pyromod\listen\listen.py", line 93, in resolve_listener
    await self.user_callback(client, message, *args)
  File "C:\WorkSpace\Apps\Bots\File-Sharing-Bot\middlewares\__init__.py", line 9, in ensure_user_indb
    await check_and_add_user(msg.chat, msg.from_user)
  File "C:\WorkSpace\Apps\Bots\File-Sharing-Bot\helper_func.py", line 113, in check_and_add_user
    exists = await present_user(telegram_id=msg_from.id)
                                            ^^^^^^^^^^^
AttributeError: 'NoneType' object has no attribute 'id'
[17-May-24 21:08:58 - WARNING] - pyrogram.connection.connection - Unable to connect due to network issues: Connection timed out
[17-May-24 21:09:09 - WARNING] - pyrogram.connection.connection - Unable to connect due to network issues: Connection timed out
[17-May-24 21:09:20 - WARNING] - pyrogram.connection.connection - Unable to connect due to network issues: Connection timed out
[17-May-24 21:09:21 - WARNING] - pyrogram.connection.connection - Connection failed! Trying again...
[17-May-24 21:10:26 - WARNING] - pyrogram.connection.connection - Unable to connect due to network issues: Connection timed out
[17-May-24 21:10:45 - WARNING] - pyrogram.connection.connection - Unable to connect due to network issues: Connection timed out
[17-May-24 21:50:25 - WARNING] - pyrogram.connection.connection - Unable to connect due to network issues: Connection timed out
[17-May-24 21:52:05 - WARNING] - pyrogram.connection.connection - Unable to connect due to network issues: Connection timed out
[17-May-24 21:52:16 - WARNING] - pyrogram.connection.connection - Unable to connect due to network issues: Connection timed out
[17-May-24 21:52:27 - WARNING] - pyrogram.connection.connection - Unable to connect due to network issues: Connection timed out
[17-May-24 21:52:28 - WARNING] - pyrogram.connection.connection - Connection failed! Trying again...
[17-May-24 21:52:38 - WARNING] - pyrogram.connection.connection - Unable to connect due to network issues: Connection timed out
[17-May-24 21:52:49 - WARNING] - pyrogram.connection.connection - Unable to connect due to network issues: Connection timed out
[17-May-24 21:52:54 - WARNING] - pyrogram.connection.connection - Unable to connect due to network issues: [WinError 1236] The network connection was aborted by the local system
[17-May-24 21:52:55 - WARNING] - pyrogram.connection.connection - Connection failed! Trying again...
[17-May-24 21:52:55 - WARNING] - pyrogram.connection.connection - Unable to connect due to network issues: [WinError 1231] The network location cannot be reached. For information about network troubleshooting, see Windows Help
[17-May-24 21:52:56 - WARNING] - pyrogram.connection.connection - Unable to connect due to network issues: [WinError 1231] The network location cannot be reached. For information about network troubleshooting, see Windows Help
[17-May-24 21:52:57 - WARNING] - pyrogram.connection.connection - Unable to connect due to network issues: [WinError 1231] The network location cannot be reached. For information about network troubleshooting, see Windows Help
[17-May-24 21:52:58 - WARNING] - pyrogram.connection.connection - Connection failed! Trying again...
[17-May-24 21:53:08 - WARNING] - pyrogram.connection.connection - Unable to connect due to network issues: Connection timed out
[17-May-24 21:55:23 - WARNING] - pyrogram.connection.connection - Unable to connect due to network issues: Connection timed out
[17-May-24 21:55:34 - WARNING] - pyrogram.connection.connection - Unable to connect due to network issues: Connection timed out
[18-May-24 06:44:04 - ERROR] - pyrogram.dispatcher - 'NoneType' object has no attribute 'id'
Traceback (most recent call last):
  File "C:\Users\manfr\AppData\Roaming\Python\Python311\site-packages\pyrogram\dispatcher.py", line 240, in handler_worker
    await handler.callback(self.client, *args)
  File "C:\Users\manfr\AppData\Roaming\Python\Python311\site-packages\pyromod\listen\listen.py", line 93, in resolve_listener
    await self.user_callback(client, message, *args)
  File "C:\WorkSpace\Apps\Bots\File-Sharing-Bot\middlewares\__init__.py", line 9, in ensure_user_indb
    await check_and_add_user(msg.chat, msg.from_user)
  File "C:\WorkSpace\Apps\Bots\File-Sharing-Bot\helper_func.py", line 113, in check_and_add_user
    exists = await present_user(telegram_id=msg_from.id)
                                            ^^^^^^^^^^^
AttributeError: 'NoneType' object has no attribute 'id'
[18-May-24 07:17:03 - WARNING] - pyrogram.connection.connection - Unable to connect due to network issues: [WinError 1231] The network location cannot be reached. For information about network troubleshooting, see Windows Help
[18-May-24 07:30:07 - ERROR] - pyrogram.dispatcher - 'NoneType' object has no attribute 'id'
Traceback (most recent call last):
  File "C:\Users\manfr\AppData\Roaming\Python\Python311\site-packages\pyrogram\dispatcher.py", line 240, in handler_worker
    await handler.callback(self.client, *args)
  File "C:\Users\manfr\AppData\Roaming\Python\Python311\site-packages\pyromod\listen\listen.py", line 93, in resolve_listener
    await self.user_callback(client, message, *args)
  File "C:\WorkSpace\Apps\Bots\File-Sharing-Bot\middlewares\__init__.py", line 9, in ensure_user_indb
    await check_and_add_user(msg.chat, msg.from_user)
  File "C:\WorkSpace\Apps\Bots\File-Sharing-Bot\helper_func.py", line 113, in check_and_add_user
    exists = await present_user(telegram_id=msg_from.id)
                                            ^^^^^^^^^^^
AttributeError: 'NoneType' object has no attribute 'id'
[18-May-24 07:32:04 - ERROR] - pyrogram.dispatcher - 'NoneType' object has no attribute 'id'
Traceback (most recent call last):
  File "C:\Users\manfr\AppData\Roaming\Python\Python311\site-packages\pyrogram\dispatcher.py", line 240, in handler_worker
    await handler.callback(self.client, *args)
  File "C:\Users\manfr\AppData\Roaming\Python\Python311\site-packages\pyromod\listen\listen.py", line 93, in resolve_listener
    await self.user_callback(client, message, *args)
  File "C:\WorkSpace\Apps\Bots\File-Sharing-Bot\middlewares\__init__.py", line 9, in ensure_user_indb
    await check_and_add_user(msg.chat, msg.from_user)
  File "C:\WorkSpace\Apps\Bots\File-Sharing-Bot\helper_func.py", line 113, in check_and_add_user
    exists = await present_user(telegram_id=msg_from.id)
                                            ^^^^^^^^^^^
AttributeError: 'NoneType' object has no attribute 'id'
[18-May-24 08:15:53 - WARNING] - pyrogram.connection.connection - Unable to connect due to network issues: Connection timed out
[18-May-24 08:19:39 - INFO] - aiohttp.access - 127.0.0.1 [18/May/2024:07:19:39 +0000] "GET /favicon.ico HTTP/1.1" 404 173 "http://localhost:8080/de" "Mozilla/5.0 (Windows NT 10.0; Win64; x64) AppleWebKit/537.36 (KHTML, like Gecko) Chrome/124.0.0.0 Safari/537.36"
[18-May-24 08:19:41 - INFO] - aiohttp.access - 127.0.0.1 [18/May/2024:07:19:41 +0000] "GET /de HTTP/1.1" 200 169 "-" "Mozilla/5.0 (Windows NT 10.0; Win64; x64) AppleWebKit/537.36 (KHTML, like Gecko) Chrome/124.0.0.0 Safari/537.36"
[18-May-24 08:19:42 - INFO] - aiohttp.access - 127.0.0.1 [18/May/2024:07:19:42 +0000] "GET /de HTTP/1.1" 200 169 "-" "Mozilla/5.0 (Windows NT 10.0; Win64; x64) AppleWebKit/537.36 (KHTML, like Gecko) Chrome/124.0.0.0 Safari/537.36"
[18-May-24 08:19:43 - INFO] - aiohttp.access - 127.0.0.1 [18/May/2024:07:19:43 +0000] "GET /de HTTP/1.1" 200 169 "-" "Mozilla/5.0 (Windows NT 10.0; Win64; x64) AppleWebKit/537.36 (KHTML, like Gecko) Chrome/124.0.0.0 Safari/537.36"
[18-May-24 08:19:43 - INFO] - aiohttp.access - 127.0.0.1 [18/May/2024:07:19:43 +0000] "GET /de HTTP/1.1" 200 169 "-" "Mozilla/5.0 (Windows NT 10.0; Win64; x64) AppleWebKit/537.36 (KHTML, like Gecko) Chrome/124.0.0.0 Safari/537.36"
[18-May-24 08:19:43 - INFO] - aiohttp.access - 127.0.0.1 [18/May/2024:07:19:43 +0000] "GET /de HTTP/1.1" 200 169 "-" "Mozilla/5.0 (Windows NT 10.0; Win64; x64) AppleWebKit/537.36 (KHTML, like Gecko) Chrome/124.0.0.0 Safari/537.36"
[18-May-24 08:19:43 - INFO] - aiohttp.access - 127.0.0.1 [18/May/2024:07:19:43 +0000] "GET /de HTTP/1.1" 200 169 "-" "Mozilla/5.0 (Windows NT 10.0; Win64; x64) AppleWebKit/537.36 (KHTML, like Gecko) Chrome/124.0.0.0 Safari/537.36"
[18-May-24 08:19:44 - INFO] - aiohttp.access - 127.0.0.1 [18/May/2024:07:19:44 +0000] "GET /de HTTP/1.1" 200 169 "-" "Mozilla/5.0 (Windows NT 10.0; Win64; x64) AppleWebKit/537.36 (KHTML, like Gecko) Chrome/124.0.0.0 Safari/537.36"
[18-May-24 08:19:44 - INFO] - aiohttp.access - 127.0.0.1 [18/May/2024:07:19:44 +0000] "GET /de HTTP/1.1" 200 169 "-" "Mozilla/5.0 (Windows NT 10.0; Win64; x64) AppleWebKit/537.36 (KHTML, like Gecko) Chrome/124.0.0.0 Safari/537.36"
[18-May-24 08:19:44 - INFO] - aiohttp.access - 127.0.0.1 [18/May/2024:07:19:44 +0000] "GET /de HTTP/1.1" 200 169 "-" "Mozilla/5.0 (Windows NT 10.0; Win64; x64) AppleWebKit/537.36 (KHTML, like Gecko) Chrome/124.0.0.0 Safari/537.36"
[18-May-24 08:19:44 - INFO] - aiohttp.access - 127.0.0.1 [18/May/2024:07:19:44 +0000] "GET /de HTTP/1.1" 200 169 "-" "Mozilla/5.0 (Windows NT 10.0; Win64; x64) AppleWebKit/537.36 (KHTML, like Gecko) Chrome/124.0.0.0 Safari/537.36"
[18-May-24 08:37:51 - INFO] - root - Stop signal received (SIGINT). Exiting...
[18-May-24 08:37:51 - INFO] - bot - Bot stopped.
[18-May-24 08:43:24 - INFO] - bot - Bot Running..!

Created by 
https://t.me/stilloid
[18-May-24 08:43:24 - INFO] - bot - Lets roll
[18-May-24 08:47:27 - ERROR] - pyrogram.dispatcher - 'InlineKeyboardButton' object is not iterable
Traceback (most recent call last):
  File "C:\Users\manfr\AppData\Roaming\Python\Python311\site-packages\pyrogram\dispatcher.py", line 240, in handler_worker
    await handler.callback(self.client, *args)
  File "C:\Users\manfr\AppData\Roaming\Python\Python311\site-packages\pyromod\listen\listen.py", line 93, in resolve_listener
    await self.user_callback(client, message, *args)
  File "C:\WorkSpace\Apps\Bots\File-Sharing-Bot\injector\__init__.py", line 20, in wrapper
    return await func(client, profile, *args, **kwargs)
           ^^^^^^^^^^^^^^^^^^^^^^^^^^^^^^^^^^^^^^^^^^^^
  File "C:\WorkSpace\Apps\Bots\File-Sharing-Bot\plugins\on_message.py", line 61, in handle_message
    await reply_text.edit_text( respond_text, reply_markup=response_message_markup )
  File "C:\Users\manfr\AppData\Roaming\Python\Python311\site-packages\pyrogram\types\messages_and_media\message.py", line 2803, in edit_text
    return await self._client.edit_message_text(
           ^^^^^^^^^^^^^^^^^^^^^^^^^^^^^^^^^^^^^
  File "C:\Users\manfr\AppData\Roaming\Python\Python311\site-packages\pyrogram\methods\messages\edit_message_text.py", line 87, in edit_message_text
    reply_markup=await reply_markup.write(self) if reply_markup else None,
                 ^^^^^^^^^^^^^^^^^^^^^^^^^^^^^^
  File "C:\Users\manfr\AppData\Roaming\Python\Python311\site-packages\pyrogram\types\bots_and_keyboards\inline_keyboard_markup.py", line 62, in write
    for b in r:
TypeError: 'InlineKeyboardButton' object is not iterable
[18-May-24 08:47:45 - INFO] - root - Stop signal received (SIGINT). Exiting...
[18-May-24 08:47:45 - INFO] - bot - Bot stopped.
[18-May-24 08:47:57 - INFO] - bot - Bot Running..!

Created by 
https://t.me/stilloid
[18-May-24 08:47:57 - INFO] - bot - Lets roll
[18-May-24 08:48:59 - WARNING] - pyrogram.connection.connection - Unable to connect due to network issues: [WinError 1236] The network connection was aborted by the local system
[18-May-24 09:21:19 - INFO] - root - Stop signal received (SIGINT). Exiting...
[18-May-24 09:21:19 - INFO] - bot - Bot stopped.
[18-May-24 09:21:28 - INFO] - bot - Bot Running..!

Created by 
https://t.me/stilloid
[18-May-24 09:21:28 - INFO] - bot - Lets roll
[18-May-24 09:32:25 - INFO] - root - Stop signal received (SIGINT). Exiting...
[18-May-24 09:32:25 - INFO] - bot - Bot stopped.
[18-May-24 09:32:35 - INFO] - bot - Bot Running..!

Created by 
https://t.me/stilloid
[18-May-24 09:32:35 - INFO] - bot - Lets roll
[18-May-24 09:43:10 - INFO] - root - Stop signal received (SIGINT). Exiting...
[18-May-24 09:43:10 - INFO] - bot - Bot stopped.
[18-May-24 09:43:20 - INFO] - bot - Bot Running..!

Created by 
https://t.me/stilloid
[18-May-24 09:43:20 - INFO] - bot - Lets roll
[18-May-24 10:01:43 - INFO] - root - Stop signal received (SIGINT). Exiting...
[18-May-24 10:01:43 - INFO] - bot - Bot stopped.
[18-May-24 10:01:55 - INFO] - bot - Bot Running..!

Created by 
https://t.me/stilloid
[18-May-24 10:01:55 - INFO] - bot - Lets roll
[18-May-24 12:55:55 - ERROR] - pyrogram.dispatcher - 'NoneType' object has no attribute 'id'
Traceback (most recent call last):
  File "C:\Users\manfr\AppData\Roaming\Python\Python311\site-packages\pyrogram\dispatcher.py", line 240, in handler_worker
    await handler.callback(self.client, *args)
  File "C:\Users\manfr\AppData\Roaming\Python\Python311\site-packages\pyromod\listen\listen.py", line 93, in resolve_listener
    await self.user_callback(client, message, *args)
  File "C:\WorkSpace\Apps\Bots\File-Sharing-Bot\middlewares\__init__.py", line 9, in ensure_user_indb
    await check_and_add_user(msg.chat, msg.from_user)
  File "C:\WorkSpace\Apps\Bots\File-Sharing-Bot\helper_func.py", line 113, in check_and_add_user
    exists = await present_user(telegram_id=msg_from.id)
                                            ^^^^^^^^^^^
AttributeError: 'NoneType' object has no attribute 'id'
[18-May-24 14:03:22 - ERROR] - pyrogram.dispatcher - 'NoneType' object has no attribute 'id'
Traceback (most recent call last):
  File "C:\Users\manfr\AppData\Roaming\Python\Python311\site-packages\pyrogram\dispatcher.py", line 240, in handler_worker
    await handler.callback(self.client, *args)
  File "C:\Users\manfr\AppData\Roaming\Python\Python311\site-packages\pyromod\listen\listen.py", line 93, in resolve_listener
    await self.user_callback(client, message, *args)
  File "C:\WorkSpace\Apps\Bots\File-Sharing-Bot\middlewares\__init__.py", line 9, in ensure_user_indb
    await check_and_add_user(msg.chat, msg.from_user)
  File "C:\WorkSpace\Apps\Bots\File-Sharing-Bot\helper_func.py", line 113, in check_and_add_user
    exists = await present_user(telegram_id=msg_from.id)
                                            ^^^^^^^^^^^
AttributeError: 'NoneType' object has no attribute 'id'
[18-May-24 15:23:54 - WARNING] - pyrogram.connection.connection - Unable to connect due to network issues: Connection timed out
[18-May-24 15:24:05 - WARNING] - pyrogram.connection.connection - Unable to connect due to network issues: Connection timed out
[18-May-24 15:24:16 - WARNING] - pyrogram.connection.connection - Unable to connect due to network issues: Connection timed out
[18-May-24 15:24:17 - WARNING] - pyrogram.connection.connection - Connection failed! Trying again...
[18-May-24 18:22:21 - WARNING] - pyrogram.connection.connection - Unable to connect due to network issues: Connection timed out
[18-May-24 18:31:30 - ERROR] - pyrogram.dispatcher - 'NoneType' object has no attribute 'id'
Traceback (most recent call last):
  File "C:\Users\manfr\AppData\Roaming\Python\Python311\site-packages\pyrogram\dispatcher.py", line 240, in handler_worker
    await handler.callback(self.client, *args)
  File "C:\Users\manfr\AppData\Roaming\Python\Python311\site-packages\pyromod\listen\listen.py", line 93, in resolve_listener
    await self.user_callback(client, message, *args)
  File "C:\WorkSpace\Apps\Bots\File-Sharing-Bot\middlewares\__init__.py", line 9, in ensure_user_indb
    await check_and_add_user(msg.chat, msg.from_user)
  File "C:\WorkSpace\Apps\Bots\File-Sharing-Bot\helper_func.py", line 113, in check_and_add_user
    exists = await present_user(telegram_id=msg_from.id)
                                            ^^^^^^^^^^^
AttributeError: 'NoneType' object has no attribute 'id'
[18-May-24 18:31:57 - ERROR] - pyrogram.dispatcher - 'NoneType' object has no attribute 'id'
Traceback (most recent call last):
  File "C:\Users\manfr\AppData\Roaming\Python\Python311\site-packages\pyrogram\dispatcher.py", line 240, in handler_worker
    await handler.callback(self.client, *args)
  File "C:\Users\manfr\AppData\Roaming\Python\Python311\site-packages\pyromod\listen\listen.py", line 93, in resolve_listener
    await self.user_callback(client, message, *args)
  File "C:\WorkSpace\Apps\Bots\File-Sharing-Bot\middlewares\__init__.py", line 9, in ensure_user_indb
    await check_and_add_user(msg.chat, msg.from_user)
  File "C:\WorkSpace\Apps\Bots\File-Sharing-Bot\helper_func.py", line 113, in check_and_add_user
    exists = await present_user(telegram_id=msg_from.id)
                                            ^^^^^^^^^^^
AttributeError: 'NoneType' object has no attribute 'id'
[18-May-24 18:43:21 - WARNING] - pyrogram.connection.connection - Unable to connect due to network issues: Connection timed out
[18-May-24 18:54:44 - ERROR] - pyrogram.dispatcher - 'NoneType' object has no attribute 'id'
Traceback (most recent call last):
  File "C:\Users\manfr\AppData\Roaming\Python\Python311\site-packages\pyrogram\dispatcher.py", line 240, in handler_worker
    await handler.callback(self.client, *args)
  File "C:\Users\manfr\AppData\Roaming\Python\Python311\site-packages\pyromod\listen\listen.py", line 93, in resolve_listener
    await self.user_callback(client, message, *args)
  File "C:\WorkSpace\Apps\Bots\File-Sharing-Bot\middlewares\__init__.py", line 9, in ensure_user_indb
    await check_and_add_user(msg.chat, msg.from_user)
  File "C:\WorkSpace\Apps\Bots\File-Sharing-Bot\helper_func.py", line 113, in check_and_add_user
    exists = await present_user(telegram_id=msg_from.id)
                                            ^^^^^^^^^^^
AttributeError: 'NoneType' object has no attribute 'id'
[18-May-24 19:46:34 - WARNING] - pyrogram.connection.connection - Unable to connect due to network issues: Connection timed out
[18-May-24 19:47:37 - WARNING] - pyrogram.connection.connection - Unable to connect due to network issues: Connection timed out
[18-May-24 19:47:48 - WARNING] - pyrogram.connection.connection - Unable to connect due to network issues: Connection timed out
[18-May-24 19:48:11 - WARNING] - pyrogram.connection.connection - Unable to connect due to network issues: Connection timed out
[18-May-24 19:48:31 - WARNING] - pyrogram.connection.connection - Unable to connect due to network issues: Connection timed out
[18-May-24 19:50:30 - WARNING] - pyrogram.connection.connection - Unable to connect due to network issues: Connection timed out
[18-May-24 19:54:54 - WARNING] - pyrogram.connection.connection - Unable to connect due to network issues: Connection timed out
[18-May-24 19:55:55 - WARNING] - pyrogram.connection.connection - Unable to connect due to network issues: Connection timed out
[18-May-24 19:57:34 - WARNING] - pyrogram.connection.connection - Unable to connect due to network issues: Connection timed out
[18-May-24 19:57:45 - WARNING] - pyrogram.connection.connection - Unable to connect due to network issues: Connection timed out
[18-May-24 20:01:29 - WARNING] - pyrogram.connection.connection - Unable to connect due to network issues: Connection timed out
[18-May-24 20:01:40 - WARNING] - pyrogram.connection.connection - Unable to connect due to network issues: Connection timed out
[18-May-24 20:01:51 - WARNING] - pyrogram.connection.connection - Unable to connect due to network issues: Connection timed out
[18-May-24 20:01:52 - WARNING] - pyrogram.connection.connection - Connection failed! Trying again...
[18-May-24 20:02:59 - WARNING] - pyrogram.connection.connection - Unable to connect due to network issues: Connection timed out
[18-May-24 20:04:19 - WARNING] - pyrogram.connection.connection - Unable to connect due to network issues: Connection timed out
[18-May-24 20:06:31 - WARNING] - pyrogram.connection.connection - Unable to connect due to network issues: Connection timed out
[18-May-24 20:06:42 - WARNING] - pyrogram.connection.connection - Unable to connect due to network issues: Connection timed out
[18-May-24 20:12:06 - WARNING] - pyrogram.connection.connection - Unable to connect due to network issues: Connection timed out
[18-May-24 20:19:27 - WARNING] - pyrogram.connection.connection - Unable to connect due to network issues: Connection timed out
[18-May-24 20:19:38 - WARNING] - pyrogram.connection.connection - Unable to connect due to network issues: Connection timed out
[18-May-24 20:19:49 - WARNING] - pyrogram.connection.connection - Unable to connect due to network issues: Connection timed out
[18-May-24 20:19:50 - WARNING] - pyrogram.connection.connection - Connection failed! Trying again...
[18-May-24 20:20:00 - WARNING] - pyrogram.connection.connection - Unable to connect due to network issues: Connection timed out
[18-May-24 20:20:11 - WARNING] - pyrogram.connection.connection - Unable to connect due to network issues: Connection timed out
[18-May-24 20:22:21 - WARNING] - pyrogram.connection.connection - Unable to connect due to network issues: Connection timed out
[18-May-24 20:27:11 - WARNING] - pyrogram.connection.connection - Unable to connect due to network issues: Connection timed out
[18-May-24 20:27:22 - WARNING] - pyrogram.connection.connection - Unable to connect due to network issues: Connection timed out
[18-May-24 20:31:35 - WARNING] - pyrogram.connection.connection - Unable to connect due to network issues: Connection timed out
[18-May-24 20:33:21 - WARNING] - pyrogram.connection.connection - Unable to connect due to network issues: Connection timed out
[18-May-24 20:49:41 - WARNING] - pyrogram.connection.connection - Unable to connect due to network issues: Connection timed out
[18-May-24 20:59:20 - WARNING] - pyrogram.connection.connection - Unable to connect due to network issues: Connection timed out
[18-May-24 20:59:31 - WARNING] - pyrogram.connection.connection - Unable to connect due to network issues: Connection timed out
[18-May-24 21:13:36 - WARNING] - pyrogram.connection.connection - Unable to connect due to network issues: Connection timed out
[18-May-24 21:13:47 - WARNING] - pyrogram.connection.connection - Unable to connect due to network issues: Connection timed out
[18-May-24 21:13:58 - WARNING] - pyrogram.connection.connection - Unable to connect due to network issues: Connection timed out
[18-May-24 21:13:59 - WARNING] - pyrogram.connection.connection - Connection failed! Trying again...
[18-May-24 21:15:07 - WARNING] - pyrogram.connection.connection - Unable to connect due to network issues: Connection timed out
[18-May-24 21:15:18 - WARNING] - pyrogram.connection.connection - Unable to connect due to network issues: Connection timed out
[18-May-24 23:12:17 - ERROR] - pyrogram.dispatcher - 'NoneType' object has no attribute 'id'
Traceback (most recent call last):
  File "C:\Users\manfr\AppData\Roaming\Python\Python311\site-packages\pyrogram\dispatcher.py", line 240, in handler_worker
    await handler.callback(self.client, *args)
  File "C:\Users\manfr\AppData\Roaming\Python\Python311\site-packages\pyromod\listen\listen.py", line 93, in resolve_listener
    await self.user_callback(client, message, *args)
  File "C:\WorkSpace\Apps\Bots\File-Sharing-Bot\middlewares\__init__.py", line 9, in ensure_user_indb
    await check_and_add_user(msg.chat, msg.from_user)
  File "C:\WorkSpace\Apps\Bots\File-Sharing-Bot\helper_func.py", line 113, in check_and_add_user
    exists = await present_user(telegram_id=msg_from.id)
                                            ^^^^^^^^^^^
AttributeError: 'NoneType' object has no attribute 'id'
[18-May-24 23:27:01 - ERROR] - pyrogram.dispatcher - 'NoneType' object has no attribute 'id'
Traceback (most recent call last):
  File "C:\Users\manfr\AppData\Roaming\Python\Python311\site-packages\pyrogram\dispatcher.py", line 240, in handler_worker
    await handler.callback(self.client, *args)
  File "C:\Users\manfr\AppData\Roaming\Python\Python311\site-packages\pyromod\listen\listen.py", line 93, in resolve_listener
    await self.user_callback(client, message, *args)
  File "C:\WorkSpace\Apps\Bots\File-Sharing-Bot\middlewares\__init__.py", line 9, in ensure_user_indb
    await check_and_add_user(msg.chat, msg.from_user)
  File "C:\WorkSpace\Apps\Bots\File-Sharing-Bot\helper_func.py", line 113, in check_and_add_user
    exists = await present_user(telegram_id=msg_from.id)
                                            ^^^^^^^^^^^
AttributeError: 'NoneType' object has no attribute 'id'
[18-May-24 23:31:09 - ERROR] - pyrogram.dispatcher - 'NoneType' object has no attribute 'id'
Traceback (most recent call last):
  File "C:\Users\manfr\AppData\Roaming\Python\Python311\site-packages\pyrogram\dispatcher.py", line 240, in handler_worker
    await handler.callback(self.client, *args)
  File "C:\Users\manfr\AppData\Roaming\Python\Python311\site-packages\pyromod\listen\listen.py", line 93, in resolve_listener
    await self.user_callback(client, message, *args)
  File "C:\WorkSpace\Apps\Bots\File-Sharing-Bot\middlewares\__init__.py", line 9, in ensure_user_indb
    await check_and_add_user(msg.chat, msg.from_user)
  File "C:\WorkSpace\Apps\Bots\File-Sharing-Bot\helper_func.py", line 113, in check_and_add_user
    exists = await present_user(telegram_id=msg_from.id)
                                            ^^^^^^^^^^^
AttributeError: 'NoneType' object has no attribute 'id'
[19-May-24 14:47:45 - ERROR] - pyrogram.dispatcher - 'NoneType' object has no attribute 'id'
Traceback (most recent call last):
  File "C:\Users\manfr\AppData\Roaming\Python\Python311\site-packages\pyrogram\dispatcher.py", line 240, in handler_worker
    await handler.callback(self.client, *args)
  File "C:\Users\manfr\AppData\Roaming\Python\Python311\site-packages\pyromod\listen\listen.py", line 93, in resolve_listener
    await self.user_callback(client, message, *args)
  File "C:\WorkSpace\Apps\Bots\File-Sharing-Bot\middlewares\__init__.py", line 9, in ensure_user_indb
    await check_and_add_user(msg.chat, msg.from_user)
  File "C:\WorkSpace\Apps\Bots\File-Sharing-Bot\helper_func.py", line 113, in check_and_add_user
    exists = await present_user(telegram_id=msg_from.id)
                                            ^^^^^^^^^^^
AttributeError: 'NoneType' object has no attribute 'id'
[19-May-24 14:48:20 - ERROR] - pyrogram.dispatcher - 'NoneType' object has no attribute 'id'
Traceback (most recent call last):
  File "C:\Users\manfr\AppData\Roaming\Python\Python311\site-packages\pyrogram\dispatcher.py", line 240, in handler_worker
    await handler.callback(self.client, *args)
  File "C:\Users\manfr\AppData\Roaming\Python\Python311\site-packages\pyromod\listen\listen.py", line 93, in resolve_listener
    await self.user_callback(client, message, *args)
  File "C:\WorkSpace\Apps\Bots\File-Sharing-Bot\middlewares\__init__.py", line 9, in ensure_user_indb
    await check_and_add_user(msg.chat, msg.from_user)
  File "C:\WorkSpace\Apps\Bots\File-Sharing-Bot\helper_func.py", line 113, in check_and_add_user
    exists = await present_user(telegram_id=msg_from.id)
                                            ^^^^^^^^^^^
AttributeError: 'NoneType' object has no attribute 'id'
[19-May-24 16:31:57 - WARNING] - pyrogram.connection.connection - Unable to connect due to network issues: Connection timed out
[19-May-24 16:32:08 - WARNING] - pyrogram.connection.connection - Unable to connect due to network issues: Connection timed out
[19-May-24 16:50:04 - ERROR] - pyrogram.dispatcher - 'NoneType' object has no attribute 'id'
Traceback (most recent call last):
  File "C:\Users\manfr\AppData\Roaming\Python\Python311\site-packages\pyrogram\dispatcher.py", line 240, in handler_worker
    await handler.callback(self.client, *args)
  File "C:\Users\manfr\AppData\Roaming\Python\Python311\site-packages\pyromod\listen\listen.py", line 93, in resolve_listener
    await self.user_callback(client, message, *args)
  File "C:\WorkSpace\Apps\Bots\File-Sharing-Bot\middlewares\__init__.py", line 9, in ensure_user_indb
    await check_and_add_user(msg.chat, msg.from_user)
  File "C:\WorkSpace\Apps\Bots\File-Sharing-Bot\helper_func.py", line 113, in check_and_add_user
    exists = await present_user(telegram_id=msg_from.id)
                                            ^^^^^^^^^^^
AttributeError: 'NoneType' object has no attribute 'id'
[19-May-24 22:31:59 - ERROR] - pyrogram.dispatcher - 'NoneType' object has no attribute 'id'
Traceback (most recent call last):
  File "C:\Users\manfr\AppData\Roaming\Python\Python311\site-packages\pyrogram\dispatcher.py", line 240, in handler_worker
    await handler.callback(self.client, *args)
  File "C:\Users\manfr\AppData\Roaming\Python\Python311\site-packages\pyromod\listen\listen.py", line 93, in resolve_listener
    await self.user_callback(client, message, *args)
  File "C:\WorkSpace\Apps\Bots\File-Sharing-Bot\middlewares\__init__.py", line 9, in ensure_user_indb
    await check_and_add_user(msg.chat, msg.from_user)
  File "C:\WorkSpace\Apps\Bots\File-Sharing-Bot\helper_func.py", line 113, in check_and_add_user
    exists = await present_user(telegram_id=msg_from.id)
                                            ^^^^^^^^^^^
AttributeError: 'NoneType' object has no attribute 'id'
[19-May-24 22:32:09 - ERROR] - pyrogram.dispatcher - 'NoneType' object has no attribute 'id'
Traceback (most recent call last):
  File "C:\Users\manfr\AppData\Roaming\Python\Python311\site-packages\pyrogram\dispatcher.py", line 240, in handler_worker
    await handler.callback(self.client, *args)
  File "C:\Users\manfr\AppData\Roaming\Python\Python311\site-packages\pyromod\listen\listen.py", line 93, in resolve_listener
    await self.user_callback(client, message, *args)
  File "C:\WorkSpace\Apps\Bots\File-Sharing-Bot\middlewares\__init__.py", line 9, in ensure_user_indb
    await check_and_add_user(msg.chat, msg.from_user)
  File "C:\WorkSpace\Apps\Bots\File-Sharing-Bot\helper_func.py", line 113, in check_and_add_user
    exists = await present_user(telegram_id=msg_from.id)
                                            ^^^^^^^^^^^
AttributeError: 'NoneType' object has no attribute 'id'
[21-May-24 04:22:34 - WARNING] - pyrogram.connection.connection - Unable to connect due to network issues: [WinError 1232] The network location cannot be reached. For information about network troubleshooting, see Windows Help
[21-May-24 04:22:35 - WARNING] - pyrogram.connection.connection - Unable to connect due to network issues: [WinError 1232] The network location cannot be reached. For information about network troubleshooting, see Windows Help
[21-May-24 04:22:37 - WARNING] - pyrogram.connection.connection - Unable to connect due to network issues: [WinError 1232] The network location cannot be reached. For information about network troubleshooting, see Windows Help
[21-May-24 04:22:38 - WARNING] - pyrogram.connection.connection - Connection failed! Trying again...
[21-May-24 04:22:38 - WARNING] - pyrogram.connection.connection - Unable to connect due to network issues: [WinError 1232] The network location cannot be reached. For information about network troubleshooting, see Windows Help
[21-May-24 04:22:39 - WARNING] - pyrogram.connection.connection - Unable to connect due to network issues: [WinError 1232] The network location cannot be reached. For information about network troubleshooting, see Windows Help
[21-May-24 04:32:55 - INFO] - root - Stop signal received (SIGINT). Exiting...
[21-May-24 04:32:55 - INFO] - bot - Bot stopped.
[21-May-24 04:33:09 - INFO] - bot - Bot Running..!

Created by 
https://t.me/stilloid
[21-May-24 04:33:09 - INFO] - bot - Lets roll
[21-May-24 05:05:11 - INFO] - root - Stop signal received (SIGINT). Exiting...
[21-May-24 05:05:11 - INFO] - bot - Bot stopped.
[21-May-24 05:05:22 - INFO] - bot - Bot Running..!

Created by 
https://t.me/stilloid
[21-May-24 05:05:22 - INFO] - bot - Lets roll
[21-May-24 05:07:55 - INFO] - root - Stop signal received (SIGINT). Exiting...
[21-May-24 05:07:55 - INFO] - bot - Bot stopped.
[21-May-24 05:08:03 - INFO] - bot - Bot Running..!

Created by 
https://t.me/stilloid
[21-May-24 05:08:03 - INFO] - bot - Lets roll
[21-May-24 05:14:46 - INFO] - root - Stop signal received (SIGINT). Exiting...
[21-May-24 05:14:46 - INFO] - bot - Bot stopped.
[21-May-24 05:14:56 - INFO] - bot - Bot Running..!

Created by 
https://t.me/stilloid
[21-May-24 05:14:56 - INFO] - bot - Lets roll
[21-May-24 05:15:41 - INFO] - root - Stop signal received (SIGINT). Exiting...
[21-May-24 05:15:41 - INFO] - bot - Bot stopped.
[21-May-24 05:16:08 - INFO] - bot - Bot Running..!

Created by 
https://t.me/stilloid
[21-May-24 05:16:08 - INFO] - bot - Lets roll
[21-May-24 05:16:45 - INFO] - root - Stop signal received (SIGINT). Exiting...
[21-May-24 05:16:45 - INFO] - bot - Bot stopped.
[21-May-24 05:16:57 - INFO] - bot - Bot Running..!

Created by 
https://t.me/stilloid
[21-May-24 05:16:57 - INFO] - bot - Lets roll
[21-May-24 05:22:55 - INFO] - root - Stop signal received (SIGINT). Exiting...
[21-May-24 05:22:55 - INFO] - bot - Bot stopped.
[21-May-24 05:23:05 - INFO] - bot - Bot Running..!

Created by 
https://t.me/stilloid
[21-May-24 05:23:05 - INFO] - bot - Lets roll
[21-May-24 05:23:23 - ERROR] - pyrogram.dispatcher - list.append() takes exactly one argument (2 given)
Traceback (most recent call last):
  File "C:\Users\manfr\AppData\Roaming\Python\Python311\site-packages\pyrogram\dispatcher.py", line 240, in handler_worker
    await handler.callback(self.client, *args)
  File "C:\Users\manfr\AppData\Roaming\Python\Python311\site-packages\pyromod\listen\listen.py", line 93, in resolve_listener
    await self.user_callback(client, message, *args)
  File "C:\WorkSpace\Apps\Bots\File-Sharing-Bot\injector\__init__.py", line 20, in wrapper
    return await func(client, profile, *args, **kwargs)
           ^^^^^^^^^^^^^^^^^^^^^^^^^^^^^^^^^^^^^^^^^^^^
  File "C:\WorkSpace\Apps\Bots\File-Sharing-Bot\plugins\on_message.py", line 38, in handle_message
    headline, reply_markup = await rspmsg.response_when_is_question(profile.id, msg_text)
                             ^^^^^^^^^^^^^^^^^^^^^^^^^^^^^^^^^^^^^^^^^^^^^^^^^^^^^^^^^^^^
  File "C:\WorkSpace\Apps\Bots\File-Sharing-Bot\responses\__init__.py", line 115, in response_when_is_question
    buttons.append(
TypeError: list.append() takes exactly one argument (2 given)
[21-May-24 05:24:05 - INFO] - root - Stop signal received (SIGINT). Exiting...
[21-May-24 05:24:05 - INFO] - bot - Bot stopped.
[21-May-24 05:24:14 - INFO] - bot - Bot Running..!

Created by 
https://t.me/stilloid
[21-May-24 05:24:14 - INFO] - bot - Lets roll
[21-May-24 05:29:01 - INFO] - root - Stop signal received (SIGINT). Exiting...
[21-May-24 05:29:01 - INFO] - bot - Bot stopped.
[21-May-24 05:29:10 - INFO] - bot - Bot Running..!

Created by 
https://t.me/stilloid
[21-May-24 05:29:10 - INFO] - bot - Lets roll
[21-May-24 05:31:28 - INFO] - root - Stop signal received (SIGINT). Exiting...
[21-May-24 05:31:28 - INFO] - bot - Bot stopped.
[21-May-24 05:31:39 - INFO] - bot - Bot Running..!

Created by 
https://t.me/stilloid
[21-May-24 05:31:39 - INFO] - bot - Lets roll
[21-May-24 05:33:38 - INFO] - root - Stop signal received (SIGINT). Exiting...
[21-May-24 05:33:38 - INFO] - bot - Bot stopped.
[21-May-24 05:33:47 - INFO] - bot - Bot Running..!

Created by 
https://t.me/stilloid
[21-May-24 05:33:47 - INFO] - bot - Lets roll
[21-May-24 05:34:20 - INFO] - root - Stop signal received (SIGINT). Exiting...
[21-May-24 05:34:20 - INFO] - bot - Bot stopped.
[21-May-24 05:34:29 - INFO] - bot - Bot Running..!

Created by 
https://t.me/stilloid
[21-May-24 05:34:29 - INFO] - bot - Lets roll
[21-May-24 05:34:32 - ERROR] - pyrogram.dispatcher - Telegram says: [400 BUTTON_URL_INVALID] - The button url is invalid (caused by "messages.SendMessage")
Traceback (most recent call last):
  File "C:\Users\manfr\AppData\Roaming\Python\Python311\site-packages\pyrogram\dispatcher.py", line 240, in handler_worker
    await handler.callback(self.client, *args)
  File "C:\Users\manfr\AppData\Roaming\Python\Python311\site-packages\pyromod\listen\listen.py", line 93, in resolve_listener
    await self.user_callback(client, message, *args)
  File "C:\WorkSpace\Apps\Bots\File-Sharing-Bot\injector\__init__.py", line 20, in wrapper
    return await func(client, profile, *args, **kwargs)
           ^^^^^^^^^^^^^^^^^^^^^^^^^^^^^^^^^^^^^^^^^^^^
  File "C:\WorkSpace\Apps\Bots\File-Sharing-Bot\plugins\on_message.py", line 39, in handle_message
    return await message.reply_text(headline, reply_markup=reply_markup, quote=True)
           ^^^^^^^^^^^^^^^^^^^^^^^^^^^^^^^^^^^^^^^^^^^^^^^^^^^^^^^^^^^^^^^^^^^^^^^^^
  File "C:\Users\manfr\AppData\Roaming\Python\Python311\site-packages\pyrogram\types\messages_and_media\message.py", line 970, in reply_text
    return await self._client.send_message(
           ^^^^^^^^^^^^^^^^^^^^^^^^^^^^^^^^
  File "C:\Users\manfr\AppData\Roaming\Python\Python311\site-packages\pyrogram\methods\messages\send_message.py", line 126, in send_message
    r = await self.invoke(
        ^^^^^^^^^^^^^^^^^^
  File "C:\Users\manfr\AppData\Roaming\Python\Python311\site-packages\pyrogram\methods\advanced\invoke.py", line 79, in invoke
    r = await self.session.invoke(
        ^^^^^^^^^^^^^^^^^^^^^^^^^^
  File "C:\Users\manfr\AppData\Roaming\Python\Python311\site-packages\pyrogram\session\session.py", line 389, in invoke
    return await self.send(query, timeout=timeout)
           ^^^^^^^^^^^^^^^^^^^^^^^^^^^^^^^^^^^^^^^
  File "C:\Users\manfr\AppData\Roaming\Python\Python311\site-packages\pyrogram\session\session.py", line 357, in send
    RPCError.raise_it(result, type(data))
  File "C:\Users\manfr\AppData\Roaming\Python\Python311\site-packages\pyrogram\errors\rpc_error.py", line 91, in raise_it
    raise getattr(
pyrogram.errors.exceptions.bad_request_400.ButtonUrlInvalid: Telegram says: [400 BUTTON_URL_INVALID] - The button url is invalid (caused by "messages.SendMessage")
[21-May-24 05:34:51 - ERROR] - pyrogram.dispatcher - Telegram says: [400 BUTTON_URL_INVALID] - The button url is invalid (caused by "messages.SendMessage")
Traceback (most recent call last):
  File "C:\Users\manfr\AppData\Roaming\Python\Python311\site-packages\pyrogram\dispatcher.py", line 240, in handler_worker
    await handler.callback(self.client, *args)
  File "C:\Users\manfr\AppData\Roaming\Python\Python311\site-packages\pyromod\listen\listen.py", line 93, in resolve_listener
    await self.user_callback(client, message, *args)
  File "C:\WorkSpace\Apps\Bots\File-Sharing-Bot\injector\__init__.py", line 20, in wrapper
    return await func(client, profile, *args, **kwargs)
           ^^^^^^^^^^^^^^^^^^^^^^^^^^^^^^^^^^^^^^^^^^^^
  File "C:\WorkSpace\Apps\Bots\File-Sharing-Bot\plugins\on_message.py", line 39, in handle_message
    return await message.reply_text(headline, reply_markup=reply_markup, quote=True)
           ^^^^^^^^^^^^^^^^^^^^^^^^^^^^^^^^^^^^^^^^^^^^^^^^^^^^^^^^^^^^^^^^^^^^^^^^^
  File "C:\Users\manfr\AppData\Roaming\Python\Python311\site-packages\pyrogram\types\messages_and_media\message.py", line 970, in reply_text
    return await self._client.send_message(
           ^^^^^^^^^^^^^^^^^^^^^^^^^^^^^^^^
  File "C:\Users\manfr\AppData\Roaming\Python\Python311\site-packages\pyrogram\methods\messages\send_message.py", line 126, in send_message
    r = await self.invoke(
        ^^^^^^^^^^^^^^^^^^
  File "C:\Users\manfr\AppData\Roaming\Python\Python311\site-packages\pyrogram\methods\advanced\invoke.py", line 79, in invoke
    r = await self.session.invoke(
        ^^^^^^^^^^^^^^^^^^^^^^^^^^
  File "C:\Users\manfr\AppData\Roaming\Python\Python311\site-packages\pyrogram\session\session.py", line 389, in invoke
    return await self.send(query, timeout=timeout)
           ^^^^^^^^^^^^^^^^^^^^^^^^^^^^^^^^^^^^^^^
  File "C:\Users\manfr\AppData\Roaming\Python\Python311\site-packages\pyrogram\session\session.py", line 357, in send
    RPCError.raise_it(result, type(data))
  File "C:\Users\manfr\AppData\Roaming\Python\Python311\site-packages\pyrogram\errors\rpc_error.py", line 91, in raise_it
    raise getattr(
pyrogram.errors.exceptions.bad_request_400.ButtonUrlInvalid: Telegram says: [400 BUTTON_URL_INVALID] - The button url is invalid (caused by "messages.SendMessage")
[21-May-24 05:35:16 - ERROR] - pyrogram.dispatcher - Telegram says: [400 BUTTON_URL_INVALID] - The button url is invalid (caused by "messages.SendMessage")
Traceback (most recent call last):
  File "C:\Users\manfr\AppData\Roaming\Python\Python311\site-packages\pyrogram\dispatcher.py", line 240, in handler_worker
    await handler.callback(self.client, *args)
  File "C:\Users\manfr\AppData\Roaming\Python\Python311\site-packages\pyromod\listen\listen.py", line 93, in resolve_listener
    await self.user_callback(client, message, *args)
  File "C:\WorkSpace\Apps\Bots\File-Sharing-Bot\injector\__init__.py", line 20, in wrapper
    return await func(client, profile, *args, **kwargs)
           ^^^^^^^^^^^^^^^^^^^^^^^^^^^^^^^^^^^^^^^^^^^^
  File "C:\WorkSpace\Apps\Bots\File-Sharing-Bot\plugins\on_message.py", line 39, in handle_message
    return await message.reply_text(headline, reply_markup=reply_markup, quote=True)
           ^^^^^^^^^^^^^^^^^^^^^^^^^^^^^^^^^^^^^^^^^^^^^^^^^^^^^^^^^^^^^^^^^^^^^^^^^
  File "C:\Users\manfr\AppData\Roaming\Python\Python311\site-packages\pyrogram\types\messages_and_media\message.py", line 970, in reply_text
    return await self._client.send_message(
           ^^^^^^^^^^^^^^^^^^^^^^^^^^^^^^^^
  File "C:\Users\manfr\AppData\Roaming\Python\Python311\site-packages\pyrogram\methods\messages\send_message.py", line 126, in send_message
    r = await self.invoke(
        ^^^^^^^^^^^^^^^^^^
  File "C:\Users\manfr\AppData\Roaming\Python\Python311\site-packages\pyrogram\methods\advanced\invoke.py", line 79, in invoke
    r = await self.session.invoke(
        ^^^^^^^^^^^^^^^^^^^^^^^^^^
  File "C:\Users\manfr\AppData\Roaming\Python\Python311\site-packages\pyrogram\session\session.py", line 389, in invoke
    return await self.send(query, timeout=timeout)
           ^^^^^^^^^^^^^^^^^^^^^^^^^^^^^^^^^^^^^^^
  File "C:\Users\manfr\AppData\Roaming\Python\Python311\site-packages\pyrogram\session\session.py", line 357, in send
    RPCError.raise_it(result, type(data))
  File "C:\Users\manfr\AppData\Roaming\Python\Python311\site-packages\pyrogram\errors\rpc_error.py", line 91, in raise_it
    raise getattr(
pyrogram.errors.exceptions.bad_request_400.ButtonUrlInvalid: Telegram says: [400 BUTTON_URL_INVALID] - The button url is invalid (caused by "messages.SendMessage")
[21-May-24 05:36:44 - ERROR] - pyrogram.dispatcher - Telegram says: [400 BUTTON_URL_INVALID] - The button url is invalid (caused by "messages.SendMessage")
Traceback (most recent call last):
  File "C:\Users\manfr\AppData\Roaming\Python\Python311\site-packages\pyrogram\dispatcher.py", line 240, in handler_worker
    await handler.callback(self.client, *args)
  File "C:\Users\manfr\AppData\Roaming\Python\Python311\site-packages\pyromod\listen\listen.py", line 93, in resolve_listener
    await self.user_callback(client, message, *args)
  File "C:\WorkSpace\Apps\Bots\File-Sharing-Bot\injector\__init__.py", line 20, in wrapper
    return await func(client, profile, *args, **kwargs)
           ^^^^^^^^^^^^^^^^^^^^^^^^^^^^^^^^^^^^^^^^^^^^
  File "C:\WorkSpace\Apps\Bots\File-Sharing-Bot\plugins\on_message.py", line 39, in handle_message
    return await message.reply_text(headline, reply_markup=reply_markup, quote=True)
           ^^^^^^^^^^^^^^^^^^^^^^^^^^^^^^^^^^^^^^^^^^^^^^^^^^^^^^^^^^^^^^^^^^^^^^^^^
  File "C:\Users\manfr\AppData\Roaming\Python\Python311\site-packages\pyrogram\types\messages_and_media\message.py", line 970, in reply_text
    return await self._client.send_message(
           ^^^^^^^^^^^^^^^^^^^^^^^^^^^^^^^^
  File "C:\Users\manfr\AppData\Roaming\Python\Python311\site-packages\pyrogram\methods\messages\send_message.py", line 126, in send_message
    r = await self.invoke(
        ^^^^^^^^^^^^^^^^^^
  File "C:\Users\manfr\AppData\Roaming\Python\Python311\site-packages\pyrogram\methods\advanced\invoke.py", line 79, in invoke
    r = await self.session.invoke(
        ^^^^^^^^^^^^^^^^^^^^^^^^^^
  File "C:\Users\manfr\AppData\Roaming\Python\Python311\site-packages\pyrogram\session\session.py", line 389, in invoke
    return await self.send(query, timeout=timeout)
           ^^^^^^^^^^^^^^^^^^^^^^^^^^^^^^^^^^^^^^^
  File "C:\Users\manfr\AppData\Roaming\Python\Python311\site-packages\pyrogram\session\session.py", line 357, in send
    RPCError.raise_it(result, type(data))
  File "C:\Users\manfr\AppData\Roaming\Python\Python311\site-packages\pyrogram\errors\rpc_error.py", line 91, in raise_it
    raise getattr(
pyrogram.errors.exceptions.bad_request_400.ButtonUrlInvalid: Telegram says: [400 BUTTON_URL_INVALID] - The button url is invalid (caused by "messages.SendMessage")
[21-May-24 05:37:06 - INFO] - root - Stop signal received (SIGINT). Exiting...
[21-May-24 05:37:06 - INFO] - bot - Bot stopped.
[21-May-24 05:37:15 - INFO] - bot - Bot Running..!

Created by 
https://t.me/stilloid
[21-May-24 05:37:15 - INFO] - bot - Lets roll
[21-May-24 05:38:03 - INFO] - root - Stop signal received (SIGINT). Exiting...
[21-May-24 05:38:03 - INFO] - bot - Bot stopped.
[21-May-24 05:38:12 - INFO] - bot - Bot Running..!

Created by 
https://t.me/stilloid
[21-May-24 05:38:12 - INFO] - bot - Lets roll
[21-May-24 05:40:16 - INFO] - root - Stop signal received (SIGINT). Exiting...
[21-May-24 05:40:16 - INFO] - bot - Bot stopped.
[21-May-24 05:40:25 - INFO] - bot - Bot Running..!

Created by 
https://t.me/stilloid
[21-May-24 05:40:25 - INFO] - bot - Lets roll
[21-May-24 05:42:06 - INFO] - root - Stop signal received (SIGINT). Exiting...
[21-May-24 05:42:06 - INFO] - bot - Bot stopped.
[21-May-24 05:42:15 - INFO] - bot - Bot Running..!

Created by 
https://t.me/stilloid
[21-May-24 05:42:15 - INFO] - bot - Lets roll
[21-May-24 05:43:09 - INFO] - root - Stop signal received (SIGINT). Exiting...
[21-May-24 05:43:09 - INFO] - bot - Bot stopped.
[21-May-24 05:43:17 - INFO] - bot - Bot Running..!

Created by 
https://t.me/stilloid
[21-May-24 05:43:17 - INFO] - bot - Lets roll
[21-May-24 05:45:09 - INFO] - root - Stop signal received (SIGINT). Exiting...
[21-May-24 05:45:09 - INFO] - bot - Bot stopped.
[21-May-24 05:45:18 - INFO] - bot - Bot Running..!

Created by 
https://t.me/stilloid
[21-May-24 05:45:18 - INFO] - bot - Lets roll
[21-May-24 05:46:05 - INFO] - root - Stop signal received (SIGINT). Exiting...
[21-May-24 05:46:05 - INFO] - bot - Bot stopped.
[21-May-24 05:46:14 - INFO] - bot - Bot Running..!

Created by 
https://t.me/stilloid
[21-May-24 05:46:14 - INFO] - bot - Lets roll
[21-May-24 05:49:18 - INFO] - root - Stop signal received (SIGINT). Exiting...
[21-May-24 05:49:18 - INFO] - bot - Bot stopped.
[21-May-24 05:50:27 - INFO] - bot - Bot Running..!

Created by 
https://t.me/stilloid
[21-May-24 05:50:27 - INFO] - bot - Lets roll
